Workbook

Sheet Data
A1: Platform | B1: Title | C1: Salary | D1: Skill | E1: Experience | F1: Degree | G1: Job Type | H1: Benefits | I1: Location | J1: Experience Group | K1: Area Type | L1: Benefits Score
A2: Jobsdb | B2: System Analyst | C2: 45000 | D2: API,IBM,Kafka,Solace,SOA | E2: 6 | F2: No | G2: Systems Analysts | H2: Medical,Statutory Leave | I2: Islands | J2: =IF(E2<=1,"0-1",IF(E2<=3,"1-3",IF(E2<=5,"3-5","5+"))) -> 5+ | K2: =VLOOKUP(I2, 'HK 18 Districts by Area Type'!A:B,2,FALSE) -> Industrial | L2: =IF(H2="",0,LEN(H2)-LEN(SUBSTITUTE(H2,",",""))+1) -> 2
A3: Jobsdb | B3: Senior System Analyst | C3: 71500 | D3: WAF,SDN,CISCO | E3: 10 | F3: No | G3: Networks & Systems Administration | I3: Wan Chai | J3: =IF(E3<=1,"0-1",IF(E3<=3,"1-3",IF(E3<=5,"3-5","5+"))) -> 5+ | K3: =VLOOKUP(I3, 'HK 18 Districts by Area Type'!A:B,2,FALSE) -> Commercial | L3: =IF(H3="",0,LEN(H3)-LEN(SUBSTITUTE(H3,",",""))+1) -> 0
A4: Jobsdb | B4: Senior Technical System engineer (Cloud) | C4: 52500 | D4: DevOps,API,AKS,K8S,OpenShift | E4: 5 | F4: Yes | G4: Networks & Systems Administration | I4: Wong Tai Sin | J4: =IF(E4<=1,"0-1",IF(E4<=3,"1-3",IF(E4<=5,"3-5","5+"))) -> 3-5 | K4: =VLOOKUP(I4, 'HK 18 Districts by Area Type'!A:B,2,FALSE) -> Residential | L4: =IF(H4="",0,LEN(H4)-LEN(SUBSTITUTE(H4,",",""))+1) -> 0
A5: Jobsdb | B5: System Controller Manager | C5: 55000 | D5: Linux,Unix,ERP | E5: 5 | F5: No | G5: Programme & Project Management | I5: Sham Shui Po | J5: =IF(E5<=1,"0-1",IF(E5<=3,"1-3",IF(E5<=5,"3-5","5+"))) -> 3-5 | K5: =VLOOKUP(I5, 'HK 18 Districts by Area Type'!A:B,2,FALSE) -> Industrial | L5: =IF(H5="",0,LEN(H5)-LEN(SUBSTITUTE(H5,",",""))+1) -> 0
A6: Jobsdb | B6: IT officer | C6: 25000 | D6: WordPress,WeCom,VOIP | E6: 2 | F6: No | G6: Help Desk & IT Support | H6: 13th Month Salaries,Overtime pay | I6: Yau Tsim Mong | J6: =IF(E6<=1,"0-1",IF(E6<=3,"1-3",IF(E6<=5,"3-5","5+"))) -> 1-3 | K6: =VLOOKUP(I6, 'HK 18 Districts by Area Type'!A:B,2,FALSE) -> Commercial | L6: =IF(H6="",0,LEN(H6)-LEN(SUBSTITUTE(H6,",",""))+1) -> 2
A7: Jobsdb | B7: Support Analyst | C7: 45000 | D7: java,SQL,Hibernate,Spring,Oracle | E7: 2 | F7: Yes | G7: Help Desk & IT Support | H7: 5-day Work Week | I7: Kwun Tong | J7: =IF(E7<=1,"0-1",IF(E7<=3,"1-3",IF(E7<=5,"3-5","5+"))) -> 1-3 | K7: =VLOOKUP(I7, 'HK 18 Districts by Area Type'!A:B,2,FALSE) -> Industrial | L7: =IF(H7="",0,LEN(H7)-LEN(SUBSTITUTE(H7,",",""))+1) -> 1
A8: Jobsdb | B8: Senior Deskside Support Engineer | C8: 25000 | D8: windows OS platform,Apple MAC OS platform | E8: 3 | F8: No | G8: Engineering - Software | H8: 5-day Work Week | I8: Yau Tsim Mong | J8: =IF(E8<=1,"0-1",IF(E8<=3,"1-3",IF(E8<=5,"3-5","5+"))) -> 1-3 | K8: =VLOOKUP(I8, 'HK 18 Districts by Area Type'!A:B,2,FALSE) -> Commercial | L8: =IF(H8="",0,LEN(H8)-LEN(SUBSTITUTE(H8,",",""))+1) -> 1
A9: Jobsdb | B9: Senior IT Officer | C9: 33500 | D9: Vmware,HyperV,Azure,AWS | E9: 3 | F9: Yes | G9: Programme & Project Management | I9: Tai Po | J9: =IF(E9<=1,"0-1",IF(E9<=3,"1-3",IF(E9<=5,"3-5","5+"))) -> 1-3 | K9: =VLOOKUP(I9, 'HK 18 Districts by Area Type'!A:B,2,FALSE) -> Mixed-use | L9: =IF(H9="",0,LEN(H9)-LEN(SUBSTITUTE(H9,",",""))+1) -> 0
A10: Jobsdb | B10: Java Data Architect | C10: 111000 | D10: java,Kafka,Hadoop,DevOps | E10: 15 | F10: Yes | G10: Developers/Programmers | I10: Southern | J10: =IF(E10<=1,"0-1",IF(E10<=3,"1-3",IF(E10<=5,"3-5","5+"))) -> 5+ | K10: =VLOOKUP(I10, 'HK 18 Districts by Area Type'!A:B,2,FALSE) -> Residential | L10: =IF(H10="",0,LEN(H10)-LEN(SUBSTITUTE(H10,",",""))+1) -> 0
A11: Jobsdb | B11: Analyst Programmer | C11: 46500 | D11: Python,NodeJS,JAVA Spring Boot,JavaScript,ReactJS,CSS | E11: 3 | F11: No | G11: Developers/Programmers | I11: Kwun Tong | J11: =IF(E11<=1,"0-1",IF(E11<=3,"1-3",IF(E11<=5,"3-5","5+"))) -> 1-3 | K11: =VLOOKUP(I11, 'HK 18 Districts by Area Type'!A:B,2,FALSE) -> Industrial | L11: =IF(H11="",0,LEN(H11)-LEN(SUBSTITUTE(H11,",",""))+1) -> 0
A12: Jobsdb | B12: Senior IT Officer | C12: 29000 | D12: Windows,cloud,networking | E12: 3 | F12: No | G12: Help Desk & IT Support | I12: Central and Western | J12: =IF(E12<=1,"0-1",IF(E12<=3,"1-3",IF(E12<=5,"3-5","5+"))) -> 1-3 | K12: =VLOOKUP(I12, 'HK 18 Districts by Area Type'!A:B,2,FALSE) -> Commercial | L12: =IF(H12="",0,LEN(H12)-LEN(SUBSTITUTE(H12,",",""))+1) -> 0
A13: Jobsdb | B13: Technical System Engineer | C13: 60000 | D13: ITSM,CMDB | E13: 7 | F13: Yes | G13: Networks & Systems Administration | I13: Yau Tsim Mong | J13: =IF(E13<=1,"0-1",IF(E13<=3,"1-3",IF(E13<=5,"3-5","5+"))) -> 5+ | K13: =VLOOKUP(I13, 'HK 18 Districts by Area Type'!A:B,2,FALSE) -> Commercial | L13: =IF(H13="",0,LEN(H13)-LEN(SUBSTITUTE(H13,",",""))+1) -> 0
A14: Jobsdb | B14: Systems Engineer - Financial Services | C14: 37500 | D14: Windows,networking | E14: 5 | F14: Yes | G14: Help Desk & IT Support | I14: Southern | J14: =IF(E14<=1,"0-1",IF(E14<=3,"1-3",IF(E14<=5,"3-5","5+"))) -> 3-5 | K14: =VLOOKUP(I14, 'HK 18 Districts by Area Type'!A:B,2,FALSE) -> Residential | L14: =IF(H14="",0,LEN(H14)-LEN(SUBSTITUTE(H14,",",""))+1) -> 0
A15: Jobsdb | B15: Analyst Programmer | C15: 25000 | D15: C#,JavaScript,API | E15: 3 | F15: Yes | G15: Developers/Programmers | H15: Double pay,Medical | I15: Yuen Long | J15: =IF(E15<=1,"0-1",IF(E15<=3,"1-3",IF(E15<=5,"3-5","5+"))) -> 1-3 | K15: =VLOOKUP(I15, 'HK 18 Districts by Area Type'!A:B,2,FALSE) -> Residential | L15: =IF(H15="",0,LEN(H15)-LEN(SUBSTITUTE(H15,",",""))+1) -> 2
A16: Jobsdb | B16: AI Platform Infra Architect | C16: 65000 | D16: LLMOps,RoCE/IB,DevOpes,API | E16: 4 | F16: Yes | G16: Engineering - Software | I16: Tai Po | J16: =IF(E16<=1,"0-1",IF(E16<=3,"1-3",IF(E16<=5,"3-5","5+"))) -> 3-5 | K16: =VLOOKUP(I16, 'HK 18 Districts by Area Type'!A:B,2,FALSE) -> Mixed-use | L16: =IF(H16="",0,LEN(H16)-LEN(SUBSTITUTE(H16,",",""))+1) -> 0
A17: Jobsdb | B17: Firmware Software Engineer | C17: 27500 | D17: PLC,Modbus,MQTT,C# | E17: 3 | F17: Yes | G17: Engineering - Software | I17: Tsuen Wan | J17: =IF(E17<=1,"0-1",IF(E17<=3,"1-3",IF(E17<=5,"3-5","5+"))) -> 1-3 | K17: =VLOOKUP(I17, 'HK 18 Districts by Area Type'!A:B,2,FALSE) -> Industrial | L17: =IF(H17="",0,LEN(H17)-LEN(SUBSTITUTE(H17,",",""))+1) -> 0
A18: Jobsdb | B18: Technical Manager (Enterprise Storage) | C18: 70000 | D18: Windows,Linux | E18: 10 | F18: Yes | G18: Team Leaders | I18: Southern | J18: =IF(E18<=1,"0-1",IF(E18<=3,"1-3",IF(E18<=5,"3-5","5+"))) -> 5+ | K18: =VLOOKUP(I18, 'HK 18 Districts by Area Type'!A:B,2,FALSE) -> Residential | L18: =IF(H18="",0,LEN(H18)-LEN(SUBSTITUTE(H18,",",""))+1) -> 0
A19: Jobsdb | B19: System Analyst | C19: 45000 | D19: API,EMS,Java | E19: 6 | F19: No | G19: Systems Analysts | H19: Medical,5-day Work Week | I19: Islands | J19: =IF(E19<=1,"0-1",IF(E19<=3,"1-3",IF(E19<=5,"3-5","5+"))) -> 5+ | K19: =VLOOKUP(I19, 'HK 18 Districts by Area Type'!A:B,2,FALSE) -> Industrial | L19: =IF(H19="",0,LEN(H19)-LEN(SUBSTITUTE(H19,",",""))+1) -> 2
A20: Jobsdb | B20: AI Technical Director | C20: 100000 | D20: cloud,big data,software development | E20: 8 | F20: Yes | G20: Management | I20: Kwun Tong | J20: =IF(E20<=1,"0-1",IF(E20<=3,"1-3",IF(E20<=5,"3-5","5+"))) -> 5+ | K20: =VLOOKUP(I20, 'HK 18 Districts by Area Type'!A:B,2,FALSE) -> Industrial | L20: =IF(H20="",0,LEN(H20)-LEN(SUBSTITUTE(H20,",",""))+1) -> 0
A21: Jobsdb | B21: Contract Data Governance Manager | C21: 60000 | D21: Data Governance,Develop, monitor,continuously | E21: 5 | F21: No | G21: Database Development & Administration | I21: Kwun Tong | J21: =IF(E21<=1,"0-1",IF(E21<=3,"1-3",IF(E21<=5,"3-5","5+"))) -> 3-5 | K21: =VLOOKUP(I21, 'HK 18 Districts by Area Type'!A:B,2,FALSE) -> Industrial | L21: =IF(H21="",0,LEN(H21)-LEN(SUBSTITUTE(H21,",",""))+1) -> 0
A22: Ctgoodjobs | B22: QA Engineer | C22: 27500 | D22: LLM,GitLab,Jenkins,API,Cypress,Selenium,Playwright,TestRail,Zephyr,JavaScript,typeScript,Reac | E22: 4 | F22: Yes | G22: Quality Assurance | H22: 5-day Work Week | I22: Kwai Tsing | J22: =IF(E22<=1,"0-1",IF(E22<=3,"1-3",IF(E22<=5,"3-5","5+"))) -> 3-5 | K22: =VLOOKUP(I22, 'HK 18 Districts by Area Type'!A:B,2,FALSE) -> Industrial | L22: =IF(H22="",0,LEN(H22)-LEN(SUBSTITUTE(H22,",",""))+1) -> 1
A23: Ctgoodjobs | B23: AI Application Developer | C23: 27500 | D23: AI,CNN,AWS,Azure | E23: 2 | F23: Yes | G23: Software / Web Developer | I23: Southern | J23: =IF(E23<=1,"0-1",IF(E23<=3,"1-3",IF(E23<=5,"3-5","5+"))) -> 1-3 | K23: =VLOOKUP(I23, 'HK 18 Districts by Area Type'!A:B,2,FALSE) -> Residential | L23: =IF(H23="",0,LEN(H23)-LEN(SUBSTITUTE(H23,",",""))+1) -> 0
A24: Ctgoodjobs | B24: Junior Automation Engineer | C24: 22500 | D24: Python,JavaScript,PowerShell | E24: 3 | F24: Yes | G24: Quality Assurance | H24: 5-day Work Week | I24: Central and Western | J24: =IF(E24<=1,"0-1",IF(E24<=3,"1-3",IF(E24<=5,"3-5","5+"))) -> 1-3 | K24: =VLOOKUP(I24, 'HK 18 Districts by Area Type'!A:B,2,FALSE) -> Commercial | L24: =IF(H24="",0,LEN(H24)-LEN(SUBSTITUTE(H24,",",""))+1) -> 1
A25: Ctgoodjobs | B25: Senior Network Support | C25: 35000 | D25: Windows,Linux,Vmware,TCP,VPN | E25: 4 | F25: No | G25: Network Engineer | H25: 5-day Work Week | I25: Sham Shui Po | J25: =IF(E25<=1,"0-1",IF(E25<=3,"1-3",IF(E25<=5,"3-5","5+"))) -> 3-5 | K25: =VLOOKUP(I25, 'HK 18 Districts by Area Type'!A:B,2,FALSE) -> Industrial | L25: =IF(H25="",0,LEN(H25)-LEN(SUBSTITUTE(H25,",",""))+1) -> 1
A26: Ctgoodjobs | B26: Deskside Engineer | C26: 20000 | D26: Windows,IOS | E26: 2 | F26: No | G26: Systems / Technical Support | H26: 5-day Work Week | I26: Southern | J26: =IF(E26<=1,"0-1",IF(E26<=3,"1-3",IF(E26<=5,"3-5","5+"))) -> 1-3 | K26: =VLOOKUP(I26, 'HK 18 Districts by Area Type'!A:B,2,FALSE) -> Residential | L26: =IF(H26="",0,LEN(H26)-LEN(SUBSTITUTE(H26,",",""))+1) -> 1
A27: Ctgoodjobs | B27: Database Administrator | C27: 40000 | D27: Mysql, sql | E27: 6 | F27: Yes | G27: Database Administrator | H27: 5-day Work Week,Medical | I27: Kowloon City | J27: =IF(E27<=1,"0-1",IF(E27<=3,"1-3",IF(E27<=5,"3-5","5+"))) -> 5+ | K27: =VLOOKUP(I27, 'HK 18 Districts by Area Type'!A:B,2,FALSE) -> Residential | L27: =IF(H27="",0,LEN(H27)-LEN(SUBSTITUTE(H27,",",""))+1) -> 2
A28: Ctgoodjobs | B28: System Administrator | C28: 40000 | D28: REST,SOAP,JDBC,MQ,sql | E28: 8 | F28: No | G28: Network Engineer | H28: 5-day Work Week,Medical | I28: Kowloon City | J28: =IF(E28<=1,"0-1",IF(E28<=3,"1-3",IF(E28<=5,"3-5","5+"))) -> 5+ | K28: =VLOOKUP(I28, 'HK 18 Districts by Area Type'!A:B,2,FALSE) -> Residential | L28: =IF(H28="",0,LEN(H28)-LEN(SUBSTITUTE(H28,",",""))+1) -> 2
A29: Ctgoodjobs | B29: IT Helpdesk | C29: 20000 | D29: Windows,Active Directory | E29: 2 | F29: No | G29: Systems / Technical Support | H29: 5-day Work Week,Medical | I29: Tai Po | J29: =IF(E29<=1,"0-1",IF(E29<=3,"1-3",IF(E29<=5,"3-5","5+"))) -> 1-3 | K29: =VLOOKUP(I29, 'HK 18 Districts by Area Type'!A:B,2,FALSE) -> Mixed-use | L29: =IF(H29="",0,LEN(H29)-LEN(SUBSTITUTE(H29,",",""))+1) -> 2
A30: Ctgoodjobs | B30: Data Centre Operator | C30: 22500 | D30: Data Center operation | E30: 2 | F30: No | G30: Technical Support | H30: 5-day Work Week,Medical | I30: Kwun Tong | J30: =IF(E30<=1,"0-1",IF(E30<=3,"1-3",IF(E30<=5,"3-5","5+"))) -> 1-3 | K30: =VLOOKUP(I30, 'HK 18 Districts by Area Type'!A:B,2,FALSE) -> Industrial | L30: =IF(H30="",0,LEN(H30)-LEN(SUBSTITUTE(H30,",",""))+1) -> 2
A31: Ctgoodjobs | B31: Junior IT Support | C31: 15500 | D31: Blackberry,iOS,Android | E31: 0 | F31: No | G31: Technical Support | H31: 5-day Work Week | I31: Southern | J31: =IF(E31<=1,"0-1",IF(E31<=3,"1-3",IF(E31<=5,"3-5","5+"))) -> 0-1 | K31: =VLOOKUP(I31, 'HK 18 Districts by Area Type'!A:B,2,FALSE) -> Residential | L31: =IF(H31="",0,LEN(H31)-LEN(SUBSTITUTE(H31,",",""))+1) -> 1
A32: Ctgoodjobs | B32: System Support Engineer | C32: 32500 | D32: Windows,Linux,VMware | E32: 3 | F32: Yes | G32: System Engineer | H32: 5-day Work Week | I32: Sham Shui Po | J32: =IF(E32<=1,"0-1",IF(E32<=3,"1-3",IF(E32<=5,"3-5","5+"))) -> 1-3 | K32: =VLOOKUP(I32, 'HK 18 Districts by Area Type'!A:B,2,FALSE) -> Industrial | L32: =IF(H32="",0,LEN(H32)-LEN(SUBSTITUTE(H32,",",""))+1) -> 1
A33: Ctgoodjobs | B33: Cybersecurity Manager | C33: 72500 | D33: SIEM,NGFW,WAF,XDR,SOAR,UEBA,API,TVM,K8S | E33: 10 | F33: Yes | G33: System Engineer / Network Engineer | H33: 5-day Work Week,Medical | I33: Kwun Tong | J33: =IF(E33<=1,"0-1",IF(E33<=3,"1-3",IF(E33<=5,"3-5","5+"))) -> 5+ | K33: =VLOOKUP(I33, 'HK 18 Districts by Area Type'!A:B,2,FALSE) -> Industrial | L33: =IF(H33="",0,LEN(H33)-LEN(SUBSTITUTE(H33,",",""))+1) -> 2
A34: Ctgoodjobs | B34: Network Specialist | C34: 70000 | D34: IP,WAF,SND,web | E34: 10 | F34: No | G34: System Engineer / Network Engineer | H34: 5-day Work Week,Medical | I34: Wan Chai | J34: =IF(E34<=1,"0-1",IF(E34<=3,"1-3",IF(E34<=5,"3-5","5+"))) -> 5+ | K34: =VLOOKUP(I34, 'HK 18 Districts by Area Type'!A:B,2,FALSE) -> Commercial | L34: =IF(H34="",0,LEN(H34)-LEN(SUBSTITUTE(H34,",",""))+1) -> 2
A35: Ctgoodjobs | B35: Software Engineer | C35: 42000 | D35: SIT,UAT,LangChain,Llamlandex,CrewAI,AutoGen,JavaScript | E35: 2 | F35: No | G35: Software / Web Developer | H35: 5-day Work Week,Medical | I35: Yau Tsim Mong | J35: =IF(E35<=1,"0-1",IF(E35<=3,"1-3",IF(E35<=5,"3-5","5+"))) -> 1-3 | K35: =VLOOKUP(I35, 'HK 18 Districts by Area Type'!A:B,2,FALSE) -> Commercial | L35: =IF(H35="",0,LEN(H35)-LEN(SUBSTITUTE(H35,",",""))+1) -> 2
A36: Ctgoodjobs | B36: Assistant IT Officer | C36: 16500 | D36: Windows,Microsoft Office | E36: 1 | F36: No | G36: Systems / Technical Support | I36: Kowloon City | J36: =IF(E36<=1,"0-1",IF(E36<=3,"1-3",IF(E36<=5,"3-5","5+"))) -> 0-1 | K36: =VLOOKUP(I36, 'HK 18 Districts by Area Type'!A:B,2,FALSE) -> Residential | L36: =IF(H36="",0,LEN(H36)-LEN(SUBSTITUTE(H36,",",""))+1) -> 0
A37: Ctgoodjobs | B37: Program Manager-Insurance | C37: 77500 | D37: POS | E37: 10 | F37: Yes | G37: IT / Project Manager | H37: 5-day Work Week,Medical | I37: Kwun Tong | J37: =IF(E37<=1,"0-1",IF(E37<=3,"1-3",IF(E37<=5,"3-5","5+"))) -> 5+ | K37: =VLOOKUP(I37, 'HK 18 Districts by Area Type'!A:B,2,FALSE) -> Industrial | L37: =IF(H37="",0,LEN(H37)-LEN(SUBSTITUTE(H37,",",""))+1) -> 2
A38: Ctgoodjobs | B38: IT Support Engineer | C38: 20000 | D38: Systems / Technical Support | E38: 2 | F38: No | G38: Systems / Technical Support | H38: 5-day Work Week | I38: Yau Tsim Mong | J38: =IF(E38<=1,"0-1",IF(E38<=3,"1-3",IF(E38<=5,"3-5","5+"))) -> 1-3 | K38: =VLOOKUP(I38, 'HK 18 Districts by Area Type'!A:B,2,FALSE) -> Commercial | L38: =IF(H38="",0,LEN(H38)-LEN(SUBSTITUTE(H38,",",""))+1) -> 1
A39: Ctgoodjobs | B39: ERP Solutions Engineer | C39: 40000 | D39: Microsoft,JSON,XML,CSV | E39: 3 | F39: No | G39: Software / Web Developer | H39: 5-day Work Week,Discretionary bonus | I39: Kwun Tong | J39: =IF(E39<=1,"0-1",IF(E39<=3,"1-3",IF(E39<=5,"3-5","5+"))) -> 1-3 | K39: =VLOOKUP(I39, 'HK 18 Districts by Area Type'!A:B,2,FALSE) -> Industrial | L39: =IF(H39="",0,LEN(H39)-LEN(SUBSTITUTE(H39,",",""))+1) -> 2
A40: Ctgoodjobs | B40: Developer - IBM Maximo | C40: 30000 | D40: MIF,MEA,API,maximo,JavaScript,Python | E40: 3 | F40: Yes | G40: Database Administrator | H40: 5-day Work Week,Medical | I40: Kwun Tong | J40: =IF(E40<=1,"0-1",IF(E40<=3,"1-3",IF(E40<=5,"3-5","5+"))) -> 1-3 | K40: =VLOOKUP(I40, 'HK 18 Districts by Area Type'!A:B,2,FALSE) -> Industrial | L40: =IF(H40="",0,LEN(H40)-LEN(SUBSTITUTE(H40,",",""))+1) -> 2
...

Sheet HK 18 Districts by Area Type
A1: 18 Districts | B1: 區域性質（建議分類） | C1: 原因與特徵（簡述）
A2: Central and Western | B2: Commercial | C2: 中環、上環，金融／IT／總部集中
A3: Wan Chai | B3: Commercial | C3: 灣仔、會展、寫字樓密集
A4: Eastern | B4: Mixed-use | C4: 北角、鰂魚涌（寫字樓 + 住宅）
A5: Southern | B5: Residential | C5: 香港仔、黃竹坑（住宅為主，少量工業）
A6: Yau Tsim Mong | B6: Commercial | C6: 尖沙咀、旺角，零售＋辦公
A7: Sham Shui Po | B7: Industrial | C7: 工廈、IT 零售、創科空間
A8: Kowloon City | B8: Residential | C8: 純住宅為主（紅磡例外）
A9: Wong Tai Sin | B9: Residential | C9: 公屋／居住區
A10: Kwun Tong | B10: Industrial | C10: 觀塘、牛頭角，工廈 + IT 公司
A11: Sai Kung | B11: Residential | C11: 將軍澳（大型住宅新市鎮）
A12: Tsuen Wan | B12: Industrial | C12: 荃灣工貿混合、工廈多
... A19: Islands | B19: Industrial | C19: 機場、航運、數據中心

Sheet analysis
A1: Salary Comparison Across Job Platforms | G1: Average Experience Requirement by Platform
A2: Platform | B2: Average of Salary | C2: Median of Salary | D2: Count of Job | G2: Platform | H2: Average of Experience
A3: Ctgoodjobs | B3: 34525 | C3: 28750 | D3: 20 | G3: Ctgoodjobs | H3: 3.9
A4: Jobsdb | B4: 51450 | C4: 45750 | D4: 20 | G4: Jobsdb | H4: 5.4
A5: Recruit | B5: 25173.25 | C5: 23250 | D5: 20 | G5: Recruit | H5: 2.1
A6: Grand Total | B6: 37049.417 | C6: 27500 | D6: 60 | G6: Grand Total | H6: 3.8
A10: Salary by Experience Level | G10: Degree Requirement Distribution by Platform
A11: Experience | B11: Average of Salary | C11: Count | G11: Degree-Y&N
A12: 0-1 | B12: 21202.5 | C12: 12 | G12: Platform | H12: No | I12: Yes | J12: Grand Total
A13: 1-3 | B13: 27424.423 | C13: 26 | G13: Ctgoodjobs | H13: 0.6 | I13: 0.4 | J13: 1
A14: 3-5 | B14: 47500 | C14: 9 | G14: Jobsdb | H14: 0.45 | I14: 0.55 | J14: 1
A15: 5+ | B15: 63692.308 | C15: 13 | G15: Recruit | H15: 0.85 | I15: 0.15 | J15: 1
A16: Grand Total | B16: 37049.417 | C16: 60 | G16: Grand Total | H16: 0.63333333 | I16: 0.36666667 | J16: 1
A19: Impact of Degree Requirement on Salary | G19: Distribution of IT Jobs by Location
A20: Degree | B20: Average of Salary | C20: Count | G20: Location | H20: Count of Job | I20: %
A21: No | B21: 31078.026 | C21: 38 | G21: Commercial | H21: 11 | I21: 0.18333333
A22: Yes | B22: 47363.636 | C22: 22 | G22: Industrial | H22: 24 | I22: 0.4
A23: Grand Total | B23: 37049.417 | C23: 60 | G23: Mixed-use | H23: 6 | I23: 0.1
G24: Residential | H24: 19 | I24: 0.31666667
G25: Grand Total | H25: 60 | I25: 1
A26: Impact of Experience Level on Salary
A28: Experience Group | B28: 0-1 | G28: The Relationship Between Salary and Benefits
G29: Benefits Score | H29: Average of Salary
A30: Row Labels | B30: Average of Salary | C30: Count | G30: 0 | H30: 43258.6
A31: No | B31: 20857.273 | C31: 11 | G31: 1 | H31: 26526.316
A32: Yes | B32: 25000 | C32: 1 | G32: 2 | H32: 39843.75
A33: Grand Total | B33: 21202.5 | C33: 12 | G33: Grand Total | H33: 37049.417
A35: Experience Group | B35: 1-3
A37: Row Labels | B37: Average of Salary | C37: Count
A38: No | B38: 26149.118 | C38: 17
A39: Yes | B39: 29833.333 | C39: 9
A40: Grand Total | B40: 27424.423 | C40: 26
A42: Experience Group | B42: 3-5
A44: Row Labels | B44: Average of Salary | C44: Count
A45: No | B45: 52500 | C45: 4
A46: Yes | B46: 43500 | C46: 5
A47: Grand Total | B47: 47500 | C47: 9
A49: Experience Group | B49: 5+
A51: Row Labels | B51: Average of Salary | C51: Count
A52: No | B52: 49500 | C52: 6
...
